2017 15:39:59 INFO  * Running on http://127.0.0.1:5000/ (Press CTRL+C to quit)
2017 15:40:02 INFO 127.0.0.1 - - [30/Aug/2017 15:40:02] "GET /testhome/ HTTP/1.1" 200 -
2017 15:40:02 ERROR Exception on /favicon.ico [GET]
Traceback (most recent call last):
  File "/Library/Python/2.7/site-packages/flask/app.py", line 1817, in wsgi_app
    response = self.full_dispatch_request()
  File "/Library/Python/2.7/site-packages/flask/app.py", line 1477, in full_dispatch_request
    rv = self.handle_user_exception(e)
  File "/Library/Python/2.7/site-packages/flask/app.py", line 1370, in handle_user_exception
    return self.handle_http_exception(e)
  File "/Library/Python/2.7/site-packages/flask/app.py", line 1330, in handle_http_exception
    return handler(e)
  File "/Users/Administrator/zyf/EmailFlask/app/auth/views.py", line 850, in page_not_found
    return render_template('404.html', u=session['username']), 404
  File "/Library/Python/2.7/site-packages/werkzeug/local.py", line 368, in <lambda>
    __getitem__ = lambda x, i: x._get_current_object()[i]
KeyError: 'username'
2017 15:40:02 INFO 127.0.0.1 - - [30/Aug/2017 15:40:02] "GET /favicon.ico HTTP/1.1" 500 -
2017 15:40:02 ERROR Error on request:
Traceback (most recent call last):
  File "/Library/Python/2.7/site-packages/werkzeug/serving.py", line 180, in run_wsgi
    execute(self.server.app)
  File "/Library/Python/2.7/site-packages/werkzeug/serving.py", line 168, in execute
    application_iter = app(environ, start_response)
  File "/Library/Python/2.7/site-packages/flask/app.py", line 1836, in __call__
    return self.wsgi_app(environ, start_response)
  File "/Library/Python/2.7/site-packages/flask/app.py", line 1820, in wsgi_app
    response = self.make_response(self.handle_exception(e))
  File "/Library/Python/2.7/site-packages/flask/app.py", line 1410, in handle_exception
    return handler(e)
  File "/Users/Administrator/zyf/EmailFlask/app/auth/views.py", line 856, in server_interval
    return render_template('500.html', u=session['username']), 500
  File "/Library/Python/2.7/site-packages/werkzeug/local.py", line 368, in <lambda>
    __getitem__ = lambda x, i: x._get_current_object()[i]
KeyError: 'username'
2017 15:47:30 INFO 127.0.0.1 - - [30/Aug/2017 15:47:30] "GET /testhome/ HTTP/1.1" 200 -
2017 15:47:30 INFO 127.0.0.1 - - [30/Aug/2017 15:47:30] "GET /testhome/ HTTP/1.1" 200 -
2017 15:47:30 INFO 127.0.0.1 - - [30/Aug/2017 15:47:30] "GET /testhome/ HTTP/1.1" 200 -
2017 15:47:30 INFO 127.0.0.1 - - [30/Aug/2017 15:47:30] "GET /testhome/ HTTP/1.1" 200 -
2017 15:47:30 INFO 127.0.0.1 - - [30/Aug/2017 15:47:30] "GET /testhome/ HTTP/1.1" 200 -
2017 15:47:33 INFO 127.0.0.1 - - [30/Aug/2017 15:47:33] "GET /testhome/ HTTP/1.1" 200 -
2017 15:47:33 ERROR Exception on /favicon.ico [GET]
Traceback (most recent call last):
  File "/Library/Python/2.7/site-packages/flask/app.py", line 1817, in wsgi_app
    response = self.full_dispatch_request()
  File "/Library/Python/2.7/site-packages/flask/app.py", line 1477, in full_dispatch_request
    rv = self.handle_user_exception(e)
  File "/Library/Python/2.7/site-packages/flask/app.py", line 1370, in handle_user_exception
    return self.handle_http_exception(e)
  File "/Library/Python/2.7/site-packages/flask/app.py", line 1330, in handle_http_exception
    return handler(e)
  File "/Users/Administrator/zyf/EmailFlask/app/auth/views.py", line 850, in page_not_found
    return render_template('404.html', u=session['username']), 404
  File "/Library/Python/2.7/site-packages/werkzeug/local.py", line 368, in <lambda>
    __getitem__ = lambda x, i: x._get_current_object()[i]
KeyError: 'username'
2017 15:47:33 INFO 127.0.0.1 - - [30/Aug/2017 15:47:33] "GET /favicon.ico HTTP/1.1" 500 -
2017 15:47:33 ERROR Error on request:
Traceback (most recent call last):
  File "/Library/Python/2.7/site-packages/werkzeug/serving.py", line 180, in run_wsgi
    execute(self.server.app)
  File "/Library/Python/2.7/site-packages/werkzeug/serving.py", line 168, in execute
    application_iter = app(environ, start_response)
  File "/Library/Python/2.7/site-packages/flask/app.py", line 1836, in __call__
    return self.wsgi_app(environ, start_response)
  File "/Library/Python/2.7/site-packages/flask/app.py", line 1820, in wsgi_app
    response = self.make_response(self.handle_exception(e))
  File "/Library/Python/2.7/site-packages/flask/app.py", line 1410, in handle_exception
    return handler(e)
  File "/Users/Administrator/zyf/EmailFlask/app/auth/views.py", line 856, in server_interval
    return render_template('500.html', u=session['username']), 500
  File "/Library/Python/2.7/site-packages/werkzeug/local.py", line 368, in <lambda>
    __getitem__ = lambda x, i: x._get_current_object()[i]
KeyError: 'username'
2017 15:47:37 DEBUG admin登录2017-08-30 15:47:37
2017 15:47:37 INFO 127.0.0.1 - - [30/Aug/2017 15:47:37] "POST /testhome/ HTTP/1.1" 200 -
2017 15:47:37 INFO 127.0.0.1 - - [30/Aug/2017 15:47:37] "GET /static/css/index.css HTTP/1.1" 200 -
2017 15:47:38 INFO 127.0.0.1 - - [30/Aug/2017 15:47:38] "GET /static/icon/bgi.jpeg HTTP/1.1" 200 -
2017 15:47:38 INFO 127.0.0.1 - - [30/Aug/2017 15:47:38] "GET /favicon.ico HTTP/1.1" 404 -
